//Assignment 5
//Q1.Handling Division by Zero 
//Read two numbers and perform division. Use try-catch-finally. Catch 
//DivideByZeroException and display “Division by zero is not allowed.” In the finally block 
//display “Execution completed.” Ensure finally executes regardless of exceptions. 

//using System;
//class DivisionExample
//{
//    static void Main()
//    {
//        try
//        {
//            Console.Write("Enter numerator: ");
//            int num1 = Convert.ToInt32(Console.ReadLine());

//            Console.Write("Enter denominator: ");
//            int num2 = Convert.ToInt32(Console.ReadLine());

//            int result = num1 / num2;   // May throw DivideByZeroException

//            Console.WriteLine("Result = " + result);
//        }
//        catch (DivideByZeroException)
//        {
//            Console.WriteLine("Division by zero is not allowed.");
//        }
//        finally
//        {
//            Console.WriteLine("Execution completed.");
//        }
//    }
//}


//Q2.Multiple Catch Blocks 
//Read console input and convert to int. Handle FormatException, OverflowException, and a 
//generic Exception, with distinct messages. 

//using System;
//class MultipleCatchExample
//{
//    static void Main()
//    {
//        try
//        {
//            Console.Write("Enter a number: ");
//            int number = Convert.ToInt32(Console.ReadLine()); // May throw exceptions

//            Console.WriteLine("You entered: " + number);
//        }
//        catch (FormatException)
//        {
//            Console.WriteLine("Invalid input format. Please enter a valid integer.");
//        }
//        catch (OverflowException)
//        {
//            Console.WriteLine("Number too large or too small for an Int32.");
//        }
//        catch (Exception ex)
//        {
//            Console.WriteLine("An unexpected error occurred: " + ex.Message);
//        }
//        finally
//        {
//            Console.WriteLine("Execution completed.");
//        }
//    }
//}


//Q3.Custom Exception — NegativeSalaryException 
//Define NegativeSalaryException : Exception.If entered salary < 0, throw it and handle with a 
//clear error message.

//using System;
//public class NegativeSalaryException : Exception
//{
//    public NegativeSalaryException(string message) : base(message)
//    {
//    }
//}

//public class Program
//{
//    public static void CheckSalary()
//    {
//        try
//        {
//            Console.Write("Enter salary: ");
//            double salary = Convert.ToDouble(Console.ReadLine());

//            if (salary < 0)
//                throw new NegativeSalaryException("Salary cannot be negative.");

//            Console.WriteLine("Salary is valid: " + salary);
//        }
//        catch (NegativeSalaryException ex)
//        {
//            Console.WriteLine("Error: " + ex.Message);
//        }
//        catch (FormatException)
//        {
//            Console.WriteLine("Error: Please enter a valid numeric value.");
//        }
//    }

//    public static void Main(string[] args)
//    {
//        CheckSalary();
//    }
//}



//Q4.Banking Scenario — InsufficientBalanceException 
//Simulate withdrawal: if withdrawal > balance, throw custom InsufficientBalanceException;
//otherwise print remaining balance.


//using System;
//public class InsufficientBalanceException : Exception
//{
//    public InsufficientBalanceException(string message) : base(message)
//    {
//    }
//}

//public class Program
//{
//    public static void WithDraw()
//    {
//        double balance = 5000;

//        try
//        {
//            Console.Write("Enter amount to withdraw: ");
//            double amount = Convert.ToDouble(Console.ReadLine());

//            if (amount > balance)
//                throw new InsufficientBalanceException("Insufficient balance for this withdrawal.");

//            balance -= amount;
//            Console.WriteLine("Withdrawal successful! Remaining balance is: " + balance);
//        }
//        catch (InsufficientBalanceException ex)
//        {
//            Console.WriteLine("Error: " + ex.Message);

//        }
//        catch (FormatException)
//        {
//            Console.WriteLine("Error: Please enter a valid numeric amount.");
//        }
//    }

//    public static void Main(string[] args)
//    {
//        WithDraw();
//    }
//}



//Q5.Student Marks Validation 
//Student class stores marks(0–100).If input outside range, throw InvalidMarksException. 
//Demonstrate validation and handling in Main(). 


//using System;
//public class InvalidMarksException : Exception
//{
//    public InvalidMarksException(string message) : base(message)
//    {
//    }
//}
//public class Student
//{
//    public int Marks { get; private set; }

//    public void setMarks(int marks)
//    {
//        if (marks < 0 || marks > 100)
//            throw new InvalidMarksException("Marks must be between 0 and 100.");

//        Marks = marks;
//    }
//}

//public class Program
//{
//    public static void validateMarks()
//    {
//        try
//        {
//            Console.Write("Enter student marks: ");

//            int marks = Convert.ToInt32(Console.ReadLine());

//            Student stu = new Student();
//            stu.setMarks(marks);

//            Console.WriteLine("Marks set successfully: " + stu.Marks);
//        }
//        catch (InvalidMarksException ex)
//        {
//            Console.WriteLine("Error: " + ex.Message);
//        }
//    }

//    public static void ZeroDevision() { }
//    public static void multiCatch() { }
//    public static void CheckSalary() { }
//    public static void withDraw() { }

//    static void Main(string[] args)
//    {
//        ZeroDevision();
//        multiCatch();
//        CheckSalary();
//        withDraw();
//        validateMarks();
//    }
//}




//MCQ Questions 

//1. Which of the following keywords is used to handle exceptions in C#? 
//A. throw  
//B. try  
//C. catch  
//D. finally 
//ANS:C


//2. What does the finally block do in C#? 
//A. Executes only when no exception occurs 
//B. Executes only when exception occurs 
//C. Executes always, whether exception occurs or not 
//D. Executes only for system exceptions 
//ANS:C

//3. Which class is the base for all exceptions in C#? 
//A.ApplicationException B.Exception C.SystemException D.RuntimeException.
//ANS:-B

//4.What happens if an exception is not handled in any method? 
//A. The program terminates abnormally 
//B. The compiler throws an error 
//C. CLR ignores it 
//D. It restarts automatically 
//ANS:-A

//5. Which statement is used to manually raise an exception? 
//A. raise B. throw C. throws D. raiseException 
//ANS:-B

//6. What will be the output of dividing by zero in C#? 
//A. Infinity 
//B. NaN 
//C. DivideByZeroException 
//D. ArithmeticException 
//ANS:-C

//7. Which of the following is true about multiple catch blocks? 
//A. The order of catch blocks does not matter 
//B. More specific exceptions must appear before general ones 
//C. Only one catch block is allowed 
//D. Catch blocks cannot be nested 
//ANS:-B

//8. Can a finally block be used without a catch block? 
//A. No B. Yes C. Only in static methods D.Only with throw 
//ANS:-B

//9. Predict the output
//using System; 
//class Test
//{
//    static void Main()
//    {
//        try
//        {
//            int x = 10, y = 0;
//            int z = x / y;
//            Console.WriteLine("Result: " + z);
//        }
//        catch (DivideByZeroException)
//        {
//            Console.Write("Division by zero not allowed |");
//        }
//        finally
//        {
//            Console.Write(" Finally block executed");
//        }
//    }
//}

//A.Result: 0
//B.Division by zero not allowed | Finally block executed 
//C. Compile-time error 
//D. Program terminates abnormally 
//ANS:-B

//10. Which exception occurs when you access an array element beyond its limit? 
//A. IndexOutOfRangeException 
//B. ArrayLimitException 
//C. OverflowException 
//D. ArgumentException 
//ANS:-A

//11. What does the keyword throw; inside a catch block do? 
//A. Rethrows the same exception 
//B. Throws a new exception
//C.Terminates the program
//D.Ignores the exception
//ANS:-A

//12. Predict the output
//try {
//    int[] arr = { 10, 20, 30 };
//    Console.WriteLine(arr[3]);
//} 
//catch (DivideByZeroException){
//    Console.WriteLine("Divide by zero");
//} 
//catch (IndexOutOfRangeException){
//    Console.WriteLine("Index error");
//} 
//finally{
//    Console.WriteLine("End of program");
//}
//A.
//Divide by zero 
//End of program 
//B. 
//Index error 
//End of program 
//C. Only End of program  D. Program terminated abnormally 
//ANS:-B

//14. Predict the output
//try{
//    int x = int.Parse("123A");
//    Console.WriteLine("Number: " + x);
//} 
//catch (FormatException){
//    Console.WriteLine("Invalid number format");
//}
//A.Number: 123A
//B.Invalid number format 
//C. Compile-time error 
//D. Program terminates abnormally 
//ANS:-B

//15. Which block executes when an exception occurs in the try block? 
//A. try B. finally C. catch D. throw
//ANS:-C

//Q16.True or False 
//In C#, every user-defined (custom) exception class must directly inherit from the 
//System.Exception class or one of its derived classes. 
//ANS:-TRUE

//17.What is exception propagation ?
//A.Forwarding the exception to the next statement 
//B. Passing an exception up the call stack until caught 
//C. Ignoring the exception 
//D. Retrying code execution
//ANS:-B


//18.Which block is optional in try-catch-finally structure?
//A. try B. catch C. finally D.Both B and C
//ANS:-D

//19.What will happen if both try and finally blocks have return statements ?
//A. try’s return executes
//B. finally’s return overrides try’s
//C.Both execute sequentially
//D.Compile - time error
//ANS:-B

//20.Which of the following statements about custom exceptions is correct? 
//A. Must inherit from Exception or ApplicationException 
//B. Cannot include constructors 
//C. Cannot be thrown 
//D. Handled only by CLR
//ANS:-A